Workbook

Sheet Start Here
A1: MedDecode game content template (master list + Tiles, Sort, Dissect, Build)
A3: What this is | B3: The one place MedDecode instructors write and approve game content. Each game reads only rows marked Ready (Match Pairs for Tiles, Sort Items for Sort, Dissect Terms for Dissect, Build Cases and Build Word List for Build).
A4: Where to type | B4: Yellow cells. Grey formula columns (Game-ready?, Conflict check) fill in on their own.
A5: Example rows | B5: The 12 rows already on Match Pairs are Claude's drafts, marked Draft. Check each one, fix anything wrong, then set Status to Approved and add your name and the date.
A6: Approval rule | B6: A row is Ready when Status = Approved and both Approved by and Approval date are filled in. We recommend a second instructor review for Symptom → Term and Level 4 rows.
A7: Conflict group | B7: If two answers could fit one tile (hyper- and poly- both mean 'excessive'), give both pairs the same conflict group. The game never puts them on the same board.
A8: Wrong-match nudge | B8: One short clue per pair, shown when a student picks the wrong partner. Point toward the answer without giving it.
A9: Images | B9: Put the file name in Tile B image file and keep the image, with its license, in the shared image folder. Use only images you made or that carry an open license (for example CC BY), and record the credit.
A10: Symptom rows | B10: Use wording like 'a symptom commonly associated with…'. A symptom tile should not imply a diagnosis.
A12: Pairs on file | B12: =COUNTA('Match Pairs'!D2:D201) -> 12
A13: Pairs game-ready | B13: =COUNTIF('Match Pairs'!X2:X201,"Ready") -> 0
A14: Pairs still in draft or review | B14: =COUNTIF('Match Pairs'!T2:T201,"Draft")+COUNTIF('Match Pairs'!T2:T201,"In review") -> 12
A15: Pairs needing revision | B15: =COUNTIF('Match Pairs'!T2:T201,"Needs revision") -> 0
A17: Legend
B18: Yellow = type here
A20: Sort Items sheet | B20: Content for MedDecode Sort (drag cards into categories). Card kind drives the Kind-of-word rounds; Main category drives the What-it-describes rounds.
A21: Sort items game-ready | B21: =COUNTIF('Sort Items'!P2:P201,"Ready") -> 0
A22: Sort items on file | B22: =COUNTA('Sort Items'!B2:B201) -> 70
A24: Dissect Terms sheet | B24: Terms for MedDecode Dissect. Write the split with | between pieces and list each piece's type in the same order.
A25: Dissect terms game-ready | B25: =COUNTIF('Dissect Terms'!R2:R201,"Ready") -> 0
A26: Dissect terms on file | B26: =COUNTA('Dissect Terms'!B2:B201) -> 30
A28: Build sheets | B28: Build Cases holds each patient case, its question, the answer parts and the tray. Build Word List holds every real term that can be built from the trays, so the game can say 'real term, but not the answer'.
A29: Build cases game-ready | B29: =COUNTIF('Build Cases'!Q2:Q201,"Ready") -> 0
A30: Build words game-ready | B30: =COUNTIF('Build Word List'!J2:J201,"Ready") -> 0
A32: Master lists (new) | B32: Master Word Parts and Master Terms are the single source for Tiles, Dissect and Sort. Review these first: one approved row feeds three games.
A33: Master terms on file | B33: =COUNTA('Master Terms'!A2:A400) -> 61
A34: Master terms game-ready | B34: =COUNTIF('Master Terms'!O2:O400,"Ready") -> 0

Sheet Master Word Parts
A1: Part ID | B1: Form | C1: Type | D1: Meaning | E1: Pronunciation | F1: Body system | G1: Used as a Tiles pair | H1: Written by | I1: Status | J1: Approved by | K1: Approval date | L1: Reviewer notes | M1: Game-ready?
A2: a | B2: a-, an- | C2: prefix | D2: without, absence of | E2: ay, an | F2: General | G2: Yes | H2: Claude (draft) | I2: Draft | M2: =IF(A2="","",IF(AND(I2="Approved",J2<>"",K2<>""),"Ready","Not yet")) -> Not yet
A3: brady | B3: brady- | C3: prefix | D3: slow | E3: BRAD-ee | F3: General | G3: Yes | H3: Claude (draft) | I3: Draft | M3: =IF(A3="","",IF(AND(I3="Approved",J3<>"",K3<>""),"Ready","Not yet")) -> Not yet
A4: tachy | B4: tachy- | C4: prefix | D4: fast, rapid | E4: TAK-ee | F4: General | G4: Yes | H4: Claude (draft) | I4: Draft | M4: =IF(A4="","",IF(AND(I4="Approved",J4<>"",K4<>""),"Ready","Not yet")) -> Not yet
A5: dys | B5: dys- | C5: prefix | D5: difficult, painful, abnormal | E5: dis | F5: General | G5: Yes | H5: Claude (draft) | I5: Draft | M5: =IF(A5="","",IF(AND(I5="Approved",J5<>"",K5<>""),"Ready","Not yet")) -> Not yet
A6: hyper | B6: hyper- | C6: prefix | D6: above normal, excessive | E6: HY-per | F6: General | G6: Yes | H6: Claude (draft) | I6: Draft | M6: =IF(A6="","",IF(AND(I6="Approved",J6<>"",K6<>""),"Ready","Not yet")) -> Not yet
A7: hypo | B7: hypo- | C7: prefix | D7: below normal, deficient | E7: HY-poh | F7: General | G7: Yes | H7: Claude (draft) | I7: Draft | M7: =IF(A7="","",IF(AND(I7="Approved",J7<>"",K7<>""),"Ready","Not yet")) -> Not yet
A8: peri | B8: peri- | C8: prefix | D8: around | E8: PAIR-ee | F8: General | G8: Yes | H8: Claude (draft) | I8: Draft | M8: =IF(A8="","",IF(AND(I8="Approved",J8<>"",K8<>""),"Ready","Not yet")) -> Not yet
A9: endo | B9: endo- | C9: prefix | D9: within, inner | E9: EN-doh | F9: General | G9: Yes | H9: Claude (draft) | I9: Draft | M9: =IF(A9="","",IF(AND(I9="Approved",J9<>"",K9<>""),"Ready","Not yet")) -> Not yet
A10: sub | B10: sub- | C10: prefix | D10: below, under | E10: sub | F10: General | G10: Yes | H10: Claude (draft) | I10: Draft | M10: =IF(A10="","",IF(AND(I10="Approved",J10<>"",K10<>""),"Ready","Not yet")) -> Not yet
A11: poly | B11: poly- | C11: prefix | D11: many, much | E11: POL-ee | F11: General | G11: Yes | H11: Claude (draft) | I11: Draft | M11: =IF(A11="","",IF(AND(I11="Approved",J11<>"",K11<>""),"Ready","Not yet")) -> Not yet
A12: hemi | B12: hemi- | C12: prefix | D12: half | E12: HEM-ee | F12: General | G12: Yes | H12: Claude (draft) | I12: Draft | M12: =IF(A12="","",IF(AND(I12="Approved",J12<>"",K12<>""),"Ready","Not yet")) -> Not yet
A13: dia | B13: dia- | C13: prefix | D13: through, complete | E13: DY-uh | F13: General | G13: Yes | H13: Claude (draft) | I13: Draft | M13: =IF(A13="","",IF(AND(I13="Approved",J13<>"",K13<>""),"Ready","Not yet")) -> Not yet
... A80: ous | B80: -ous | C80: suffix | D80: pertaining to | E80: us | F80: General | G80: No | H80: Claude (draft) | I80: Draft | M80: =IF(A80="","",IF(AND(I80="Approved",J80<>"",K80<>""),"Ready","Not yet")) -> Not yet
M81: =IF(A81="","",IF(AND(I81="Approved",J81<>"",K81<>""),"Ready","Not yet"))
M82: =IF(A82="","",IF(AND(I82="Approved",J82<>"",K82<>""),"Ready","Not yet"))
M83: =IF(A83="","",IF(AND(I83="Approved",J83<>"",K83<>""),"Ready","Not yet"))
M84: =IF(A84="","",IF(AND(I84="Approved",J84<>"",K84<>""),"Ready","Not yet"))
M85: =IF(A85="","",IF(AND(I85="Approved",J85<>"",K85<>""),"Ready","Not yet"))
M86: =IF(A86="","",IF(AND(I86="Approved",J86<>"",K86<>""),"Ready","Not yet"))
M87: =IF(A87="","",IF(AND(I87="Approved",J87<>"",K87<>""),"Ready","Not yet"))
M88: =IF(A88="","",IF(AND(I88="Approved",J88<>"",K88<>""),"Ready","Not yet"))
M89: =IF(A89="","",IF(AND(I89="Approved",J89<>"",K89<>""),"Ready","Not yet"))
M90: =IF(A90="","",IF(AND(I90="Approved",J90<>"",K90<>""),"Ready","Not yet"))
M91: =IF(A91="","",IF(AND(I91="Approved",J91<>"",K91<>""),"Ready","Not yet"))
M92: =IF(A92="","",IF(AND(I92="Approved",J92<>"",K92<>""),"Ready","Not yet"))
... M199: =IF(A199="","",IF(AND(I199="Approved",J199<>"",K199<>""),"Ready","Not yet"))

Sheet Master Terms
A1: Term | B1: Split (use |) | C1: Word parts | D1: Definition | E1: Pronunciation | F1: What it names | G1: Body system | H1: Level | I1: Written by | J1: Status | K1: Approved by | L1: Approval date | M1: Reviewer notes | N1: Letters check | O1: Game-ready?
A2: gastritis | B2: gastr | itis | C2: gastr/o + -itis | D2: inflammation of the stomach | E2: gas-TRY-tis | F2: condition | G2: Digestive | H2: easy | I2: Claude (draft) | J2: Draft | N2: =IF(A2="","",IF(SUBSTITUTE(SUBSTITUTE(B2," ",""),"|","")=A2,"OK","Split letters don't match")) -> OK | O2: =IF(A2="","",IF(AND(J2="Approved",K2<>"",L2<>"",N2="OK"),"Ready","Not yet")) -> Not yet
A3: hepatitis | B3: hepat | itis | C3: hepat/o + -itis | D3: inflammation of the liver | E3: hep-uh-TY-tis | F3: condition | G3: Digestive | H3: easy | I3: Claude (draft) | J3: Draft | N3: =IF(A3="","",IF(SUBSTITUTE(SUBSTITUTE(B3," ",""),"|","")=A3,"OK","Split letters don't match")) -> OK | O3: =IF(A3="","",IF(AND(J3="Approved",K3<>"",L3<>"",N3="OK"),"Ready","Not yet")) -> Not yet
A4: nephritis | B4: nephr | itis | C4: nephr/o + -itis | D4: inflammation of the kidney | E4: neh-FRY-tis | F4: condition | G4: Urinary | H4: easy | I4: Claude (draft) | J4: Draft | N4: =IF(A4="","",IF(SUBSTITUTE(SUBSTITUTE(B4," ",""),"|","")=A4,"OK","Split letters don't match")) -> OK | O4: =IF(A4="","",IF(AND(J4="Approved",K4<>"",L4<>"",N4="OK"),"Ready","Not yet")) -> Not yet
A5: dermatitis | B5: dermat | itis | C5: dermat/o + -itis | D5: inflammation of the skin | E5: der-muh-TY-tis | F5: condition | G5: Integumentary | H5: easy | I5: Claude (draft) | J5: Draft | N5: =IF(A5="","",IF(SUBSTITUTE(SUBSTITUTE(B5," ",""),"|","")=A5,"OK","Split letters don't match")) -> OK | O5: =IF(A5="","",IF(AND(J5="Approved",K5<>"",L5<>"",N5="OK"),"Ready","Not yet")) -> Not yet
A6: cystitis | B6: cyst | itis | C6: cyst/o + -itis | D6: inflammation of the urinary bladder | E6: sis-TY-tis | F6: condition | G6: Urinary | H6: easy | I6: Claude (draft) | J6: Draft | N6: =IF(A6="","",IF(SUBSTITUTE(SUBSTITUTE(B6," ",""),"|","")=A6,"OK","Split letters don't match")) -> OK | O6: =IF(A6="","",IF(AND(J6="Approved",K6<>"",L6<>"",N6="OK"),"Ready","Not yet")) -> Not yet
A7: laryngitis | B7: laryng | itis | C7: laryng/o + -itis | D7: inflammation of the larynx (voice box) | E7: lair-in-JY-tis | F7: condition | G7: Respiratory | H7: easy | I7: Claude (draft) | J7: Draft | N7: =IF(A7="","",IF(SUBSTITUTE(SUBSTITUTE(B7," ",""),"|","")=A7,"OK","Split letters don't match")) -> OK | O7: =IF(A7="","",IF(AND(J7="Approved",K7<>"",L7<>"",N7="OK"),"Ready","Not yet")) -> Not yet
A8: phlebitis | B8: phleb | itis | C8: phleb/o + -itis | D8: inflammation of a vein | E8: fleh-BY-tis | F8: condition | G8: Cardiovascular | H8: easy | I8: Claude (draft) | J8: Draft | N8: =IF(A8="","",IF(SUBSTITUTE(SUBSTITUTE(B8," ",""),"|","")=A8,"OK","Split letters don't match")) -> OK | O8: =IF(A8="","",IF(AND(J8="Approved",K8<>"",L8<>"",N8="OK"),"Ready","Not yet")) -> Not yet
A9: encephalitis | B9: encephal | itis | C9: encephal/o + -itis | D9: inflammation of the brain | E9: en-sef-uh-LY-tis | F9: condition | G9: Nervous | H9: easy | I9: Claude (draft) | J9: Draft | N9: =IF(A9="","",IF(SUBSTITUTE(SUBSTITUTE(B9," ",""),"|","")=A9,"OK","Split letters don't match")) -> OK | O9: =IF(A9="","",IF(AND(J9="Approved",K9<>"",L9<>"",N9="OK"),"Ready","Not yet")) -> Not yet
A10: glossitis | B10: gloss | itis | C10: gloss/o + -itis | D10: inflammation of the tongue | E10: glos-SY-tis | F10: condition | G10: Oral | H10: easy | I10: Claude (draft) | J10: Draft | N10: =IF(A10="","",IF(SUBSTITUTE(SUBSTITUTE(B10," ",""),"|","")=A10,"OK","Split letters don't match")) -> OK | O10: =IF(A10="","",IF(AND(J10="Approved",K10<>"",L10<>"",N10="OK"),"Ready","Not yet")) -> Not yet
A11: gingivitis | B11: gingiv | itis | C11: gingiv/o + -itis | D11: inflammation of the gums | E11: jin-jih-VY-tis | F11: condition | G11: Oral | H11: easy | I11: Claude (draft) | J11: Draft | N11: =IF(A11="","",IF(SUBSTITUTE(SUBSTITUTE(B11," ",""),"|","")=A11,"OK","Split letters don't match")) -> OK | O11: =IF(A11="","",IF(AND(J11="Approved",K11<>"",L11<>"",N11="OK"),"Ready","Not yet")) -> Not yet
A12: colitis | B12: col | itis | C12: col/o + -itis | D12: inflammation of the colon | E12: koh-LY-tis | F12: condition | G12: Digestive | H12: easy | I12: Claude (draft) | J12: Draft | N12: =IF(A12="","",IF(SUBSTITUTE(SUBSTITUTE(B12," ",""),"|","")=A12,"OK","Split letters don't match")) -> OK | O12: =IF(A12="","",IF(AND(J12="Approved",K12<>"",L12<>"",N12="OK"),"Ready","Not yet")) -> Not yet
A13: appendectomy | B13: append | ectomy | C13: append/o + -ectomy | D13: surgical removal of the appendix | E13: ap-en-DEK-tuh-mee | F13: procedure | G13: Digestive | H13: easy | I13: Claude (draft) | J13: Draft | N13: =IF(A13="","",IF(SUBSTITUTE(SUBSTITUTE(B13," ",""),"|","")=A13,"OK","Split letters don't match")) -> OK | O13: =IF(A13="","",IF(AND(J13="Approved",K13<>"",L13<>"",N13="OK"),"Ready","Not yet")) -> Not yet
... A62: electrocardiogram | B62: electr | o | cardi | o | gram | C62: electr/o + cardi/o + -gram | D62: a record of the heart's electrical activity (ECG or EKG) | E62: ee-lek-troh-KAR-dee-oh-gram | F62: test | G62: Cardiovascular | H62: hard | I62: Claude (draft) | J62: Draft | N62: =IF(A62="","",IF(SUBSTITUTE(SUBSTITUTE(B62," ",""),"|","")=A62,"OK","Split letters don't match")) -> OK | O62: =IF(A62="","",IF(AND(J62="Approved",K62<>"",L62<>"",N62="OK"),"Ready","Not yet")) -> Not yet
N63: =IF(A63="","",IF(SUBSTITUTE(SUBSTITUTE(B63," ",""),"|","")=A63,"OK","Split letters don't match")) | O63: =IF(A63="","",IF(AND(J63="Approved",K63<>"",L63<>"",N63="OK"),"Ready","Not yet"))
N64: =IF(A64="","",IF(SUBSTITUTE(SUBSTITUTE(B64," ",""),"|","")=A64,"OK","Split letters don't match")) | O64: =IF(A64="","",IF(AND(J64="Approved",K64<>"",L64<>"",N64="OK"),"Ready","Not yet"))
N65: =IF(A65="","",IF(SUBSTITUTE(SUBSTITUTE(B65," ",""),"|","")=A65,"OK","Split letters don't match")) | O65: =IF(A65="","",IF(AND(J65="Approved",K65<>"",L65<>"",N65="OK"),"Ready","Not yet"))
N66: =IF(A66="","",IF(SUBSTITUTE(SUBSTITUTE(B66," ",""),"|","")=A66,"OK","Split letters don't match")) | O66: =IF(A66="","",IF(AND(J66="Approved",K66<>"",L66<>"",N66="OK"),"Ready","Not yet"))
N67: =IF(A67="","",IF(SUBSTITUTE(SUBSTITUTE(B67," ",""),"|","")=A67,"OK","Split letters don't match")) | O67: =IF(A67="","",IF(AND(J67="Approved",K67<>"",L67<>"",N67="OK"),"Ready","Not yet"))
N68: =IF(A68="","",IF(SUBSTITUTE(SUBSTITUTE(B68," ",""),"|","")=A68,"OK","Split letters don't match")) | O68: =IF(A68="","",IF(AND(J68="Approved",K68<>"",L68<>"",N68="OK"),"Ready","Not yet"))
N69: =IF(A69="","",IF(SUBSTITUTE(SUBSTITUTE(B69," ",""),"|","")=A69,"OK","Split letters don't match")) | O69: =IF(A69="","",IF(AND(J69="Approved",K69<>"",L69<>"",N69="OK"),"Ready","Not yet"))
N70: =IF(A70="","",IF(SUBSTITUTE(SUBSTITUTE(B70," ",""),"|","")=A70,"OK","Split letters don't match")) | O70: =IF(A70="","",IF(AND(J70="Approved",K70<>"",L70<>"",N70="OK"),"Ready","Not yet"))
N71: =IF(A71="","",IF(SUBSTITUTE(SUBSTITUTE(B71," ",""),"|","")=A71,"OK","Split letters don't match")) | O71: =IF(A71="","",IF(AND(J71="Approved",K71<>"",L71<>"",N71="OK"),"Ready","Not yet"))
N72: =IF(A72="","",IF(SUBSTITUTE(SUBSTITUTE(B72," ",""),"|","")=A72,"OK","Split letters don't match")) | O72: =IF(A72="","",IF(AND(J72="Approved",K72<>"",L72<>"",N72="OK"),"Ready","Not yet"))
N73: =IF(A73="","",IF(SUBSTITUTE(SUBSTITUTE(B73," ",""),"|","")=A73,"OK","Split letters don't match")) | O73: =IF(A73="","",IF(AND(J73="Approved",K73<>"",L73<>"",N73="OK"),"Ready","Not yet"))
N74: =IF(A74="","",IF(SUBSTITUTE(SUBSTITUTE(B74," ",""),"|","")=A74,"OK","Split letters don't match")) | O74: =IF(A74="","",IF(AND(J74="Approved",K74<>"",L74<>"",N74="OK"),"Ready","Not yet"))
... N199: =IF(A199="","",IF(SUBSTITUTE(SUBSTITUTE(B199," ",""),"|","")=A199,"OK","Split letters don't match")) | O199: =IF(A199="","",IF(AND(J199="Approved",K199<>"",L199<>"",N199="OK"),"Ready","Not yet"))

Sheet Match Pairs
A1: Pair ID | B1: Set | C1: Level | D1: Tile A text | E1: Tile A kind | F1: Tile B text | G1: Tile B kind | H1: Tile B image file | I1: Body system | J1: Pronunciation (Tile A) | K1: Explanation shown after match | L1: Example terms (comma-separated) | M1: Wrong-match nudge | N1: Conflict group | O1: Why-quiz: correct answer | P1: Why-quiz: wrong option 1 | Q1: Why-quiz: wrong option 2 | R1: Programs | S1: Written by | T1: Status | U1: Approved by | V1: Approval date | W1: Reviewer notes | X1: Game-ready? | Y1: Conflict check
A2: P01 | B2: Root → Anatomy | C2: 1 Direct association | D2: cardi/o | E2: root | F2: heart | G2: anatomy | H2: heart.svg | I2: Cardiovascular | J2: KAR-dee-oh | K2: cardi/o is the combining form for the heart. | L2: cardiology, cardiomegaly, pericarditis | M2: cardi/o belongs to the cardiovascular system. Which organ pumps blood? | N2: heart | R2: All | S2: Claude (draft) | T2: Draft | X2: =IF(D2="","",IF(AND(T2="Approved",U2<>"",V2<>""),"Ready","Not yet")) -> Not yet | Y2: =IF(N2="","",IF(COUNTIF($N$2:$N$201,N2)>1,"Shares group: never same board",""))
A3: P02 | B3: Root → Anatomy | C3: 1 Direct association | D3: nephr/o | E3: root | F3: kidney | G3: anatomy | H3: kidney.svg | I3: Urinary | J3: NEF-roh | K3: nephr/o is the combining form for the kidney. | L3: nephrology, nephrectomy, nephritis | M3: nephr/o belongs to the urinary system. Which organ filters blood to make urine? | N3: kidney | R3: All | S3: Claude (draft) | T3: Draft | X3: =IF(D3="","",IF(AND(T3="Approved",U3<>"",V3<>""),"Ready","Not yet")) -> Not yet | Y3: =IF(N3="","",IF(COUNTIF($N$2:$N$201,N3)>1,"Shares group: never same board",""))
A4: P03 | B4: Root → Anatomy | C4: 1 Direct association | D4: hepat/o | E4: root | F4: liver | G4: anatomy | H4: liver.svg | I4: Digestive | J4: HEP-uh-toh | K4: hepat/o is the combining form for the liver. | L4: hepatitis, hepatomegaly, hepatology | M4: hepat/o belongs to the digestive system. Look for the large organ under the right ribs. | N4: liver | R4: All | S4: Claude (draft) | T4: Draft | X4: =IF(D4="","",IF(AND(T4="Approved",U4<>"",V4<>""),"Ready","Not yet")) -> Not yet | Y4: =IF(N4="","",IF(COUNTIF($N$2:$N$201,N4)>1,"Shares group: never same board",""))
A5: P04 | B5: Root → Anatomy | C5: 1 Direct association | D5: oste/o | E5: root | F5: bone | G5: anatomy | H5: bone.svg | I5: Skeletal | J5: OS-tee-oh | K5: oste/o is the combining form for bone. | L5: osteoporosis, osteoarthritis, osteomyelitis | M5: oste/o belongs to the skeletal system, not an organ. | N5: bone | R5: All | S5: Claude (draft) | T5: Draft | X5: =IF(D5="","",IF(AND(T5="Approved",U5<>"",V5<>""),"Ready","Not yet")) -> Not yet | Y5: =IF(N5="","",IF(COUNTIF($N$2:$N$201,N5)>1,"Shares group: never same board",""))
A6: P05 | B6: Affix → Meaning | C6: 2 Meaning | D6: tachy- | E6: prefix | F6: rapid; fast | G6: meaning | I6: General / — | J6: TAK-ee | K6: tachy- is a prefix meaning rapid or fast. | L6: tachycardia, tachypnea | M6: tachy- describes speed. Is it the fast one or the slow one? | N6: speed-fast | R6: All | S6: Claude (draft) | T6: Draft | X6: =IF(D6="","",IF(AND(T6="Approved",U6<>"",V6<>""),"Ready","Not yet")) -> Not yet | Y6: =IF(N6="","",IF(COUNTIF($N$2:$N$201,N6)>1,"Shares group: never same board",""))
A7: P06 | B7: Affix → Meaning | C7: 2 Meaning | D7: brady- | E7: prefix | F7: slow | G7: meaning | I7: General / — | J7: BRAD-ee | K7: brady- is a prefix meaning slow. | L7: bradycardia, bradypnea | M7: brady- also describes speed. Is it the fast one or the slow one? | N7: speed-slow | R7: All | S7: Claude (draft) | T7: Draft | X7: =IF(D7="","",IF(AND(T7="Approved",U7<>"",V7<>""),"Ready","Not yet")) -> Not yet | Y7: =IF(N7="","",IF(COUNTIF($N$2:$N$201,N7)>1,"Shares group: never same board",""))
A8: P07 | B8: Affix → Meaning | C8: 2 Meaning | D8: -itis | E8: suffix | F8: inflammation | G8: meaning | I8: General / — | J8: EYE-tis | K8: -itis is a suffix meaning inflammation. | L8: appendicitis, gastritis, arthritis | M8: -itis names a condition, not a procedure. | N8: inflammation | R8: All | S8: Claude (draft) | T8: Draft | X8: =IF(D8="","",IF(AND(T8="Approved",U8<>"",V8<>""),"Ready","Not yet")) -> Not yet | Y8: =IF(N8="","",IF(COUNTIF($N$2:$N$201,N8)>1,"Shares group: never same board",""))
A9: P08 | B9: Affix → Meaning | C9: 2 Meaning | D9: -ectomy | E9: suffix | F9: surgical removal | G9: meaning | I9: General / — | J9: EK-tuh-mee | K9: -ectomy is a suffix meaning surgical removal (excision). | L9: appendectomy, tonsillectomy, cholecystectomy | M9: -ectomy names a procedure, not a condition. | N9: removal | R9: All | S9: Claude (draft) | T9: Draft | X9: =IF(D9="","",IF(AND(T9="Approved",U9<>"",V9<>""),"Ready","Not yet")) -> Not yet | Y9: =IF(N9="","",IF(COUNTIF($N$2:$N$201,N9)>1,"Shares group: never same board",""))
A10: P09 | B10: Term → Definition | C10: 3 Component reasoning | D10: arthralgia | E10: term | F10: joint pain | G10: definition | I10: Musculoskeletal | J10: ar-THRAL-jee-uh | K10: arthr/o (joint) + -algia (pain) = pain in a joint. | L10: arthritis, myalgia, neuralgia | M10: Break it down: arthr/o means joint. | N10: pain | O10: arthr/o = joint, -algia = pain | P10: arthr/o = bone, -algia = swelling | Q10: arthr/o = muscle, -algia = pain | R10: All | S10: Claude (draft) | T10: Draft | X10: =IF(D10="","",IF(AND(T10="Approved",U10<>"",V10<>""),"Ready","Not yet")) -> Not yet | Y10: =IF(N10="","",IF(COUNTIF($N$2:$N$201,N10)>1,"Shares group: never same board",""))
A11: P10 | B11: Term → Definition | C11: 3 Component reasoning | D11: dyspnea | E11: term | F11: difficulty breathing | G11: definition | I11: Respiratory | J11: DISP-nee-uh | K11: dys- (difficult) + -pnea (breathing) = difficult or labored breathing. | L11: apnea, tachypnea, orthopnea | M11: Break it down: -pnea means breathing. | N11: breathing | O11: dys- = difficult, -pnea = breathing | P11: dys- = without, -pnea = heart rate | Q11: dys- = fast, -pnea = breathing | R11: All | S11: Claude (draft) | T11: Draft | X11: =IF(D11="","",IF(AND(T11="Approved",U11<>"",V11<>""),"Ready","Not yet")) -> Not yet | Y11: =IF(N11="","",IF(COUNTIF($N$2:$N$201,N11)>1,"Shares group: never same board",""))
A12: P11 | B12: Term → Definition | C12: 3 Component reasoning | D12: cyanosis | E12: term | F12: bluish discoloration of the skin | G12: definition | I12: Integumentary | J12: sy-uh-NOH-sis | K12: cyan/o (blue) + -osis (abnormal condition) = an abnormal bluish color of the skin or mucous membranes. | L12: cyanotic, acrocyanosis | M12: Break it down: cyan/o is a color. | N12: skin-color | O12: cyan/o = blue, -osis = abnormal condition | P12: cyan/o = blood, -osis = inflammation | Q12: cyan/o = cold, -osis = abnormal condition | R12: All | S12: Claude (draft) | T12: Draft | X12: =IF(D12="","",IF(AND(T12="Approved",U12<>"",V12<>""),"Ready","Not yet")) -> Not yet | Y12: =IF(N12="","",IF(COUNTIF($N$2:$N$201,N12)>1,"Shares group: never same board",""))
A13: P12 | B13: Term → Definition | C13: 3 Component reasoning | D13: hypertension | E13: term | F13: abnormally high blood pressure | G13: definition | I13: Cardiovascular | J13: hy-per-TEN-shun | K13: hyper- (above normal) + tension (pressure) = blood pressure that stays above normal. | L13: hypotension, hyperglycemia | M13: Break it down: hyper- means above normal. | N13: blood-pressure | O13: hyper- = above normal, tension = pressure | P13: hyper- = below normal, tension = pressure | Q13: hyper- = above normal, tension = muscle tightness | R13: All | S13: Claude (draft) | T13: Draft | X13: =IF(D13="","",IF(AND(T13="Approved",U13<>"",V13<>""),"Ready","Not yet")) -> Not yet | Y13: =IF(N13="","",IF(COUNTIF($N$2:$N$201,N13)>1,"Shares group: never same board",""))
X14: =IF(D14="","",IF(AND(T14="Approved",U14<>"",V14<>""),"Ready","Not yet")) | Y14: =IF(N14="","",IF(COUNTIF($N$2:$N$201,N14)>1,"Shares group: never same board",""))
X15: =IF(D15="","",IF(AND(T15="Approved",U15<>"",V15<>""),"Ready","Not yet")) | Y15: =IF(N15="","",IF(COUNTIF($N$2:$N$201,N15)>1,"Shares group: never same board",""))
X16: =IF(D16="","",IF(AND(T16="Approved",U16<>"",V16<>""),"Ready","Not yet")) | Y16: =IF(N16="","",IF(COUNTIF($N$2:$N$201,N16)>1,"Shares group: never same board",""))
X17: =IF(D17="","",IF(AND(T17="Approved",U17<>"",V17<>""),"Ready","Not yet")) | Y17: =IF(N17="","",IF(COUNTIF($N$2:$N$201,N17)>1,"Shares group: never same board",""))
X18: =IF(D18="","",IF(AND(T18="Approved",U18<>"",V18<>""),"Ready","Not yet")) | Y18: =IF(N18="","",IF(COUNTIF($N$2:$N$201,N18)>1,"Shares group: never same board",""))
X19: =IF(D19="","",IF(AND(T19="Approved",U19<>"",V19<>""),"Ready","Not yet")) | Y19: =IF(N19="","",IF(COUNTIF($N$2:$N$201,N19)>1,"Shares group: never same board",""))
X20: =IF(D20="","",IF(AND(T20="Approved",U20<>"",V20<>""),"Ready","Not yet")) | Y20: =IF(N20="","",IF(COUNTIF($N$2:$N$201,N20)>1,"Shares group: never same board",""))
X21: =IF(D21="","",IF(AND(T21="Approved",U21<>"",V21<>""),"Ready","Not yet")) | Y21: =IF(N21="","",IF(COUNTIF($N$2:$N$201,N21)>1,"Shares group: never same board",""))
X22: =IF(D22="","",IF(AND(T22="Approved",U22<>"",V22<>""),"Ready","Not yet")) | Y22: =IF(N22="","",IF(COUNTIF($N$2:$N$201,N22)>1,"Shares group: never same board",""))
X23: =IF(D23="","",IF(AND(T23="Approved",U23<>"",V23<>""),"Ready","Not yet")) | Y23: =IF(N23="","",IF(COUNTIF($N$2:$N$201,N23)>1,"Shares group: never same board",""))
X24: =IF(D24="","",IF(AND(T24="Approved",U24<>"",V24<>""),"Ready","Not yet")) | Y24: =IF(N24="","",IF(COUNTIF($N$2:$N$201,N24)>1,"Shares group: never same board",""))
X25: =IF(D25="","",IF(AND(T25="Approved",U25<>"",V25<>""),"Ready","Not yet")) | Y25: =IF(N25="","",IF(COUNTIF($N$2:$N$201,N25)>1,"Shares group: never same board",""))
... X201: =IF(D201="","",IF(AND(T201="Approved",U201<>"",V201<>""),"Ready","Not yet")) | Y201: =IF(N201="","",IF(COUNTIF($N$2:$N$201,N201)>1,"Shares group: never same board",""))

Sheet Sort Items
A1: Item ID | B1: Card text | C1: Card kind | D1: Picture file | E1: Main category | F1: Also accepted (optional) | G1: Why (shown after the drop) | H1: Note when an also-accepted bin is used | I1: Pronunciation | J1: Programs | K1: Written by | L1: Status | M1: Approved by | N1: Approval date | O1: Reviewer notes | P1: Game-ready?
A2: S01 | B2: cardi/o | C2: root / combining form | E2: Body part | G2: cardi/o means heart. | I2: KAR-dee-oh | J2: All | K2: Claude (draft) | L2: Draft | P2: =IF(B2="","",IF(AND(L2="Approved",M2<>"",N2<>""),"Ready","Not yet")) -> Not yet
A3: S02 | B3: nephr/o | C3: root / combining form | E3: Body part | G3: nephr/o means kidney. | I3: NEF-roh | J3: All | K3: Claude (draft) | L3: Draft | P3: =IF(B3="","",IF(AND(L3="Approved",M3<>"",N3<>""),"Ready","Not yet")) -> Not yet
A4: S03 | B4: oste/o | C4: root / combining form | E4: Body part | G4: oste/o means bone. | I4: OS-tee-oh | J4: All | K4: Claude (draft) | L4: Draft | P4: =IF(B4="","",IF(AND(L4="Approved",M4<>"",N4<>""),"Ready","Not yet")) -> Not yet
A5: S04 | B5: gastr/o | C5: root / combining form | E5: Body part | G5: gastr/o means stomach. | I5: GAS-troh | J5: All | K5: Claude (draft) | L5: Draft | P5: =IF(B5="","",IF(AND(L5="Approved",M5<>"",N5<>""),"Ready","Not yet")) -> Not yet
A6: S05 | B6: dermat/o | C6: root / combining form | E6: Body part | G6: dermat/o means skin. | I6: DER-muh-toh | J6: All | K6: Claude (draft) | L6: Draft | P6: =IF(B6="","",IF(AND(L6="Approved",M6<>"",N6<>""),"Ready","Not yet")) -> Not yet
A7: S06 | B7: pulmon/o | C7: root / combining form | E7: Body part | G7: pulmon/o means lung. | I7: PUL-muh-noh | J7: All | K7: Claude (draft) | L7: Draft | P7: =IF(B7="","",IF(AND(L7="Approved",M7<>"",N7<>""),"Ready","Not yet")) -> Not yet
A8: S07 | B8: myocardium | C8: full term | E8: Body part | G8: my/o (muscle) + cardi (heart) + -um (structure): the heart muscle. | I8: my-oh-KAR-dee-um | J8: All | K8: Claude (draft) | L8: Draft | P8: =IF(B8="","",IF(AND(L8="Approved",M8<>"",N8<>""),"Ready","Not yet")) -> Not yet
A9: S08 | B9: sternum | C9: full term | E9: Body part | G9: The sternum is the breastbone. | I9: STER-num | J9: All | K9: Claude (draft) | L9: Draft | P9: =IF(B9="","",IF(AND(L9="Approved",M9<>"",N9<>""),"Ready","Not yet")) -> Not yet
A10: S09 | B10: femur | C10: full term | E10: Body part | G10: The femur is the thigh bone. | I10: FEE-mur | J10: All | K10: Claude (draft) | L10: Draft | P10: =IF(B10="","",IF(AND(L10="Approved",M10<>"",N10<>""),"Ready","Not yet")) -> Not yet
A11: S10 | B11: left lower quadrant | C11: phrase | E11: Body part | G11: A region of the abdomen, used to describe where pain or findings are located. | J11: All | K11: Claude (draft) | L11: Draft | P11: =IF(B11="","",IF(AND(L11="Approved",M11<>"",N11<>""),"Ready","Not yet")) -> Not yet
A12: S11 | B12: heart | C12: picture | D12: heart.svg | E12: Body part | G12: A picture of the heart: a body part. | J12: All | K12: Claude (draft) | L12: Draft | P12: =IF(B12="","",IF(AND(L12="Approved",M12<>"",N12<>""),"Ready","Not yet")) -> Not yet
A13: S12 | B13: kidney | C13: picture | D13: kidney.svg | E13: Body part | G13: A picture of a kidney: a body part. | J13: All | K13: Claude (draft) | L13: Draft | P13: =IF(B13="","",IF(AND(L13="Approved",M13<>"",N13<>""),"Ready","Not yet")) -> Not yet
A14: S13 | B14: liver | C14: picture | D14: liver.svg | E14: Body part | G14: A picture of the liver: a body part. | J14: All | K14: Claude (draft) | L14: Draft | P14: =IF(B14="","",IF(AND(L14="Approved",M14<>"",N14<>""),"Ready","Not yet")) -> Not yet
A15: S14 | B15: -algia | C15: suffix | E15: Sign or symptom | G15: -algia means pain, a symptom (arthralgia, myalgia). | I15: AL-jee-uh | J15: All | K15: Claude (draft) | L15: Draft | P15: =IF(B15="","",IF(AND(L15="Approved",M15<>"",N15<>""),"Ready","Not yet")) -> Not yet
A16: S15 | B16: -megaly | C16: suffix | E16: Sign or symptom | F16: Condition | G16: -megaly means enlargement, usually a finding on exam or imaging (hepatomegaly). | H16: Enlargement is usually recorded as a finding (a sign), but it can also be listed as a diagnosis. | I16: MEG-uh-lee | J16: All | K16: Claude (draft) | L16: Draft | P16: =IF(B16="","",IF(AND(L16="Approved",M16<>"",N16<>""),"Ready","Not yet")) -> Not yet
A17: S16 | B17: dyspnea | C17: full term | E17: Sign or symptom | G17: dys- (difficult) + -pnea (breathing): difficulty breathing. | I17: DISP-nee-uh | J17: All | K17: Claude (draft) | L17: Draft | P17: =IF(B17="","",IF(AND(L17="Approved",M17<>"",N17<>""),"Ready","Not yet")) -> Not yet
A18: S17 | B18: cyanosis | C18: full term | E18: Sign or symptom | G18: cyan/o (blue) + -osis: bluish skin or lips, a sign of low oxygen. | I18: sy-uh-NOH-sis | J18: All | K18: Claude (draft) | L18: Draft | P18: =IF(B18="","",IF(AND(L18="Approved",M18<>"",N18<>""),"Ready","Not yet")) -> Not yet
A19: S18 | B19: tachycardia | C19: full term | E19: Sign or symptom | F19: Condition | G19: tachy- (fast) + cardi (heart) + -ia: a rapid heart rate, which you measure as a sign. | H19: Tachycardia is a sign you measure, and some forms are also diagnosed as a condition. | I19: tak-ih-KAR-dee-uh | J19: All | K19: Claude (draft) | L19: Draft | P19: =IF(B19="","",IF(AND(L19="Approved",M19<>"",N19<>""),"Ready","Not yet")) -> Not yet
A20: S19 | B20: edema | C20: full term | E20: Sign or symptom | G20: Swelling from fluid in the tissues; a sign you can see and press. | I20: eh-DEE-muh | J20: All | K20: Claude (draft) | L20: Draft | P20: =IF(B20="","",IF(AND(L20="Approved",M20<>"",N20<>""),"Ready","Not yet")) -> Not yet
A21: S20 | B21: pruritus | C21: full term | E21: Sign or symptom | G21: Itching; a symptom the patient reports. | I21: proo-RY-tus | J21: All | K21: Claude (draft) | L21: Draft | P21: =IF(B21="","",IF(AND(L21="Approved",M21<>"",N21<>""),"Ready","Not yet")) -> Not yet
A22: S21 | B22: hematuria | C22: full term | E22: Sign or symptom | G22: hemat/o (blood) + -uria (urine): blood in the urine, a sign. | I22: hee-muh-TOO-ree-uh | J22: All | K22: Claude (draft) | L22: Draft | P22: =IF(B22="","",IF(AND(L22="Approved",M22<>"",N22<>""),"Ready","Not yet")) -> Not yet
A23: S22 | B23: vertigo | C23: full term | E23: Sign or symptom | G23: A spinning sensation; a symptom the patient reports. | I23: VER-tih-goh | J23: All | K23: Claude (draft) | L23: Draft | P23: =IF(B23="","",IF(AND(L23="Approved",M23<>"",N23<>""),"Ready","Not yet")) -> Not yet
A24: S23 | B24: nausea | C24: full term | E24: Sign or symptom | G24: An urge to vomit; a symptom the patient reports. | I24: NAW-zee-uh | J24: All | K24: Claude (draft) | L24: Draft | P24: =IF(B24="","",IF(AND(L24="Approved",M24<>"",N24<>""),"Ready","Not yet")) -> Not yet
A25: S24 | B25: shortness of breath | C25: phrase | E25: Sign or symptom | G25: Plain-language form of dyspnea; a symptom. | J25: All | K25: Claude (draft) | L25: Draft | P25: =IF(B25="","",IF(AND(L25="Approved",M25<>"",N25<>""),"Ready","Not yet")) -> Not yet
A26: S25 | B26: -itis | C26: suffix | E26: Condition | G26: -itis means inflammation and names a condition (gastritis, appendicitis). | I26: EYE-tis | J26: All | K26: Claude (draft) | L26: Draft | P26: =IF(B26="","",IF(AND(L26="Approved",M26<>"",N26<>""),"Ready","Not yet")) -> Not yet
A27: S26 | B27: -osis | C27: suffix | E27: Condition | G27: -osis means abnormal condition (osteoporosis). | I27: OH-sis | J27: All | K27: Claude (draft) | L27: Draft | P27: =IF(B27="","",IF(AND(L27="Approved",M27<>"",N27<>""),"Ready","Not yet")) -> Not yet
A28: S27 | B28: -oma | C28: suffix | E28: Condition | G28: -oma means tumor or mass (carcinoma, lipoma). | I28: OH-muh | J28: All | K28: Claude (draft) | L28: Draft | P28: =IF(B28="","",IF(AND(L28="Approved",M28<>"",N28<>""),"Ready","Not yet")) -> Not yet
A29: S28 | B29: hypertension | C29: full term | E29: Condition | G29: hyper- (above normal) + tension (pressure): high blood pressure, a diagnosis. | I29: hy-per-TEN-shun | J29: All | K29: Claude (draft) | L29: Draft | P29: =IF(B29="","",IF(AND(L29="Approved",M29<>"",N29<>""),"Ready","Not yet")) -> Not yet
A30: S29 | B30: pneumonia | C30: full term | E30: Condition | G30: pneumon/o (lung) + -ia (condition): infection and inflammation of the lungs. | I30: noo-MOH-nee-uh | J30: All | K30: Claude (draft) | L30: Draft | P30: =IF(B30="","",IF(AND(L30="Approved",M30<>"",N30<>""),"Ready","Not yet")) -> Not yet
A31: S30 | B31: osteoporosis | C31: full term | E31: Condition | G31: oste/o (bone) + por/o (pore) + -osis (condition): thin, porous bones. | I31: os-tee-oh-puh-ROH-sis | J31: All | K31: Claude (draft) | L31: Draft | P31: =IF(B31="","",IF(AND(L31="Approved",M31<>"",N31<>""),"Ready","Not yet")) -> Not yet
A32: S31 | B32: gastritis | C32: full term | E32: Condition | G32: gastr/o (stomach) + -itis (inflammation). | I32: gas-TRY-tis | J32: All | K32: Claude (draft) | L32: Draft | P32: =IF(B32="","",IF(AND(L32="Approved",M32<>"",N32<>""),"Ready","Not yet")) -> Not yet
A33: S32 | B33: anemia | C33: full term | E33: Condition | G33: an- (without, lacking) + -emia (blood condition): too few red blood cells or too little hemoglobin. | I33: uh-NEE-mee-uh | J33: All | K33: Claude (draft) | L33: Draft | P33: =IF(B33="","",IF(AND(L33="Approved",M33<>"",N33<>""),"Ready","Not yet")) -> Not yet
A34: S33 | B34: myocardial infarction | C34: phrase | E34: Condition | G34: Death of heart muscle from blocked blood flow; a heart attack. | I34: my-oh-KAR-dee-ul in-FARK-shun | J34: All | K34: Claude (draft) | L34: Draft | P34: =IF(B34="","",IF(AND(L34="Approved",M34<>"",N34<>""),"Ready","Not yet")) -> Not yet
A35: S34 | B35: diabetes mellitus | C35: phrase | E35: Condition | G35: A condition of high blood sugar from too little insulin or insulin resistance. | I35: dy-uh-BEE-teez MEL-ih-tus | J35: All | K35: Claude (draft) | L35: Draft | P35: =IF(B35="","",IF(AND(L35="Approved",M35<>"",N35<>""),"Ready","Not yet")) -> Not yet
A36: S35 | B36: fracture | C36: picture | D36: fracture.svg | E36: Condition | G36: A picture of a broken bone: a fracture is an injury, so it is a condition. | J36: All | K36: Claude (draft) | L36: Draft | P36: =IF(B36="","",IF(AND(L36="Approved",M36<>"",N36<>""),"Ready","Not yet")) -> Not yet
A37: S36 | B37: -scopy | C37: suffix | E37: Test or exam | G37: -scopy means visual examination with a scope (colonoscopy). | I37: SKUH-pee | J37: All | K37: Claude (draft) | L37: Draft | P37: =IF(B37="","",IF(AND(L37="Approved",M37<>"",N37<>""),"Ready","Not yet")) -> Not yet
A38: S37 | B38: -gram | C38: suffix | E38: Test or exam | G38: -gram means a record or image (electrocardiogram). | I38: gram | J38: All | K38: Claude (draft) | L38: Draft | P38: =IF(B38="","",IF(AND(L38="Approved",M38<>"",N38<>""),"Ready","Not yet")) -> Not yet
A39: S38 | B39: -graphy | C39: suffix | E39: Test or exam | G39: -graphy means the process of recording (mammography). | I39: GRAF-ee | J39: All | K39: Claude (draft) | L39: Draft | P39: =IF(B39="","",IF(AND(L39="Approved",M39<>"",N39<>""),"Ready","Not yet")) -> Not yet
A40: S39 | B40: electrocardiogram | C40: full term | E40: Test or exam | G40: electr/o (electricity) + cardi/o (heart) + -gram (record): a record of the heart's electrical activity. | I40: ee-lek-troh-KAR-dee-oh-gram | J40: All | K40: Claude (draft) | L40: Draft | P40: =IF(B40="","",IF(AND(L40="Approved",M40<>"",N40<>""),"Ready","Not yet")) -> Not yet
...

Sheet Dissect Terms
A1: Term ID | B1: Term | C1: Level | D1: Split (use |) | E1: Part types (use |) | F1: Part meanings (use |) | G1: Textbook forms (use |) | H1: Also-accepted splits (separate with ;) | I1: Definition | J1: Pronunciation | K1: Teaching note | L1: Written by | M1: Status | N1: Approved by | O1: Approval date | P1: Reviewer notes | Q1: Letters check | R1: Game-ready?
A2: D01 | B2: gastritis | C2: easy | D2: gastr | itis | E2: root | suffix | F2: stomach | inflammation | G2: gastr/o | -itis | I2: inflammation of the stomach | J2: gas-TRY-tis | K2: The o of gastr/o is dropped because -itis begins with a vowel. | L2: Claude (draft) | M2: Draft | Q2: =IF(B2="","",IF(SUBSTITUTE(SUBSTITUTE(D2," ",""),"|","")=B2,"OK","Split letters don't match")) -> OK | R2: =IF(B2="","",IF(AND(M2="Approved",N2<>"",O2<>"",Q2="OK"),"Ready","Not yet")) -> Not yet
A3: D02 | B3: tonsillectomy | C3: easy | D3: tonsill | ectomy | E3: root | suffix | F3: tonsils | surgical removal | G3: tonsill/o | -ectomy | I3: surgical removal of the tonsils | J3: ton-sih-LEK-tuh-mee | K3: The o of tonsill/o is dropped because -ectomy begins with a vowel. | L3: Claude (draft) | M3: Draft | Q3: =IF(B3="","",IF(SUBSTITUTE(SUBSTITUTE(D3," ",""),"|","")=B3,"OK","Split letters don't match")) -> OK | R3: =IF(B3="","",IF(AND(M3="Approved",N3<>"",O3<>"",Q3="OK"),"Ready","Not yet")) -> Not yet
A4: D03 | B4: arthralgia | C4: easy | D4: arthr | algia | E4: root | suffix | F4: joint | pain | G4: arthr/o | -algia | I4: joint pain | J4: ar-THRAL-jee-uh | L4: Claude (draft) | M4: Draft | Q4: =IF(B4="","",IF(SUBSTITUTE(SUBSTITUTE(D4," ",""),"|","")=B4,"OK","Split letters don't match")) -> OK | R4: =IF(B4="","",IF(AND(M4="Approved",N4<>"",O4<>"",Q4="OK"),"Ready","Not yet")) -> Not yet
A5: D04 | B5: hepatomegaly | C5: easy | D5: hepat | o | megaly | E5: root | cv | suffix | F5: liver | links the parts | enlargement | G5: hepat/o | o | -megaly | I5: enlargement of the liver | J5: hep-uh-toh-MEG-uh-lee | K5: The o stays because -megaly begins with a consonant. | L5: Claude (draft) | M5: Draft | Q5: =IF(B5="","",IF(SUBSTITUTE(SUBSTITUTE(D5," ",""),"|","")=B5,"OK","Split letters don't match")) -> OK | R5: =IF(B5="","",IF(AND(M5="Approved",N5<>"",O5<>"",Q5="OK"),"Ready","Not yet")) -> Not yet
A6: D05 | B6: cardiology | C6: easy | D6: cardi | o | logy | E6: root | cv | suffix | F6: heart | links the parts | study of | G6: cardi/o | o | -logy | I6: the study of the heart | J6: kar-dee-OL-uh-jee | L6: Claude (draft) | M6: Draft | Q6: =IF(B6="","",IF(SUBSTITUTE(SUBSTITUTE(D6," ",""),"|","")=B6,"OK","Split letters don't match")) -> OK | R6: =IF(B6="","",IF(AND(M6="Approved",N6<>"",O6<>"",Q6="OK"),"Ready","Not yet")) -> Not yet
A7: D06 | B7: dermatitis | C7: easy | D7: dermat | itis | E7: root | suffix | F7: skin | inflammation | G7: dermat/o | -itis | I7: inflammation of the skin | J7: der-muh-TY-tis | L7: Claude (draft) | M7: Draft | Q7: =IF(B7="","",IF(SUBSTITUTE(SUBSTITUTE(D7," ",""),"|","")=B7,"OK","Split letters don't match")) -> OK | R7: =IF(B7="","",IF(AND(M7="Approved",N7<>"",O7<>"",Q7="OK"),"Ready","Not yet")) -> Not yet
A8: D07 | B8: neuralgia | C8: easy | D8: neur | algia | E8: root | suffix | F8: nerve | pain | G8: neur/o | -algia | I8: nerve pain | J8: noo-RAL-juh | L8: Claude (draft) | M8: Draft | Q8: =IF(B8="","",IF(SUBSTITUTE(SUBSTITUTE(D8," ",""),"|","")=B8,"OK","Split letters don't match")) -> OK | R8: =IF(B8="","",IF(AND(M8="Approved",N8<>"",O8<>"",Q8="OK"),"Ready","Not yet")) -> Not yet
A9: D08 | B9: appendectomy | C9: easy | D9: append | ectomy | E9: root | suffix | F9: appendix | surgical removal | G9: append/o | -ectomy | I9: surgical removal of the appendix | J9: ap-en-DEK-tuh-mee | L9: Claude (draft) | M9: Draft | Q9: =IF(B9="","",IF(SUBSTITUTE(SUBSTITUTE(D9," ",""),"|","")=B9,"OK","Split letters don't match")) -> OK | R9: =IF(B9="","",IF(AND(M9="Approved",N9<>"",O9<>"",Q9="OK"),"Ready","Not yet")) -> Not yet
A10: D09 | B10: rhinoplasty | C10: easy | D10: rhin | o | plasty | E10: root | cv | suffix | F10: nose | links the parts | surgical repair | G10: rhin/o | o | -plasty | I10: surgical repair of the nose | J10: RY-noh-plas-tee | L10: Claude (draft) | M10: Draft | Q10: =IF(B10="","",IF(SUBSTITUTE(SUBSTITUTE(D10," ",""),"|","")=B10,"OK","Split letters don't match")) -> OK | R10: =IF(B10="","",IF(AND(M10="Approved",N10<>"",O10<>"",Q10="OK"),"Ready","Not yet")) -> Not yet
A11: D10 | B11: colonoscopy | C11: easy | D11: colon | o | scopy | E11: root | cv | suffix | F11: colon | links the parts | visual examination | G11: colon/o | o | -scopy | I11: visual examination of the colon | J11: koh-luh-NOS-kuh-pee | L11: Claude (draft) | M11: Draft | Q11: =IF(B11="","",IF(SUBSTITUTE(SUBSTITUTE(D11," ",""),"|","")=B11,"OK","Split letters don't match")) -> OK | R11: =IF(B11="","",IF(AND(M11="Approved",N11<>"",O11<>"",Q11="OK"),"Ready","Not yet")) -> Not yet
A12: D11 | B12: encephalitis | C12: easy | D12: encephal | itis | E12: root | suffix | F12: brain | inflammation | G12: encephal/o | -itis | I12: inflammation of the brain | J12: en-sef-uh-LY-tis | L12: Claude (draft) | M12: Draft | Q12: =IF(B12="","",IF(SUBSTITUTE(SUBSTITUTE(D12," ",""),"|","")=B12,"OK","Split letters don't match")) -> OK | R12: =IF(B12="","",IF(AND(M12="Approved",N12<>"",O12<>"",Q12="OK"),"Ready","Not yet")) -> Not yet
A13: D12 | B13: hysterectomy | C13: easy | D13: hyster | ectomy | E13: root | suffix | F13: uterus | surgical removal | G13: hyster/o | -ectomy | I13: surgical removal of the uterus | J13: his-ter-EK-tuh-mee | L13: Claude (draft) | M13: Draft | Q13: =IF(B13="","",IF(SUBSTITUTE(SUBSTITUTE(D13," ",""),"|","")=B13,"OK","Split letters don't match")) -> OK | R13: =IF(B13="","",IF(AND(M13="Approved",N13<>"",O13<>"",Q13="OK"),"Ready","Not yet")) -> Not yet
A14: D13 | B14: tachycardia | C14: medium | D14: tachy | card | ia | E14: prefix | root | suffix | F14: fast, rapid | heart | condition | G14: tachy- | cardi/o | -ia | H14: tachy | cardia | I14: a fast heart rate | J14: tak-ih-KAR-dee-uh | L14: Claude (draft) | M14: Draft | Q14: =IF(B14="","",IF(SUBSTITUTE(SUBSTITUTE(D14," ",""),"|","")=B14,"OK","Split letters don't match")) -> OK | R14: =IF(B14="","",IF(AND(M14="Approved",N14<>"",O14<>"",Q14="OK"),"Ready","Not yet")) -> Not yet
A15: D14 | B15: bradycardia | C15: medium | D15: brady | card | ia | E15: prefix | root | suffix | F15: slow | heart | condition | G15: brady- | cardi/o | -ia | H15: brady | cardia | I15: a slow heart rate | J15: brad-ee-KAR-dee-uh | L15: Claude (draft) | M15: Draft | Q15: =IF(B15="","",IF(SUBSTITUTE(SUBSTITUTE(D15," ",""),"|","")=B15,"OK","Split letters don't match")) -> OK | R15: =IF(B15="","",IF(AND(M15="Approved",N15<>"",O15<>"",Q15="OK"),"Ready","Not yet")) -> Not yet
A16: D15 | B16: pericarditis | C16: medium | D16: peri | card | itis | E16: prefix | root | suffix | F16: around | heart | inflammation | G16: peri- | cardi/o | -itis | I16: inflammation of the sac around the heart (the pericardium) | J16: pair-ih-kar-DY-tis | L16: Claude (draft) | M16: Draft | Q16: =IF(B16="","",IF(SUBSTITUTE(SUBSTITUTE(D16," ",""),"|","")=B16,"OK","Split letters don't match")) -> OK | R16: =IF(B16="","",IF(AND(M16="Approved",N16<>"",O16<>"",Q16="OK"),"Ready","Not yet")) -> Not yet
A17: D16 | B17: endocarditis | C17: medium | D17: endo | card | itis | E17: prefix | root | suffix | F17: within | heart | inflammation | G17: endo- | cardi/o | -itis | I17: inflammation of the inner lining of the heart | J17: en-doh-kar-DY-tis | L17: Claude (draft) | M17: Draft | Q17: =IF(B17="","",IF(SUBSTITUTE(SUBSTITUTE(D17," ",""),"|","")=B17,"OK","Split letters don't match")) -> OK | R17: =IF(B17="","",IF(AND(M17="Approved",N17<>"",O17<>"",Q17="OK"),"Ready","Not yet")) -> Not yet
A18: D17 | B18: subcutaneous | C18: medium | D18: sub | cutane | ous | E18: prefix | root | suffix | F18: below, under | skin | pertaining to | G18: sub- | cutane/o | -ous | I18: pertaining to below the skin | J18: sub-kyoo-TAY-nee-us | L18: Claude (draft) | M18: Draft | Q18: =IF(B18="","",IF(SUBSTITUTE(SUBSTITUTE(D18," ",""),"|","")=B18,"OK","Split letters don't match")) -> OK | R18: =IF(B18="","",IF(AND(M18="Approved",N18<>"",O18<>"",Q18="OK"),"Ready","Not yet")) -> Not yet
A19: D18 | B19: hypoglycemia | C19: medium | D19: hypo | glyc | emia | E19: prefix | root | suffix | F19: below normal | sugar | blood condition | G19: hypo- | glyc/o | -emia | I19: below-normal blood sugar | J19: hy-poh-gly-SEE-mee-uh | L19: Claude (draft) | M19: Draft | Q19: =IF(B19="","",IF(SUBSTITUTE(SUBSTITUTE(D19," ",""),"|","")=B19,"OK","Split letters don't match")) -> OK | R19: =IF(B19="","",IF(AND(M19="Approved",N19<>"",O19<>"",Q19="OK"),"Ready","Not yet")) -> Not yet
A20: D19 | B20: hyperglycemia | C20: medium | D20: hyper | glyc | emia | E20: prefix | root | suffix | F20: above normal | sugar | blood condition | G20: hyper- | glyc/o | -emia | I20: above-normal blood sugar | J20: hy-per-gly-SEE-mee-uh | L20: Claude (draft) | M20: Draft | Q20: =IF(B20="","",IF(SUBSTITUTE(SUBSTITUTE(D20," ",""),"|","")=B20,"OK","Split letters don't match")) -> OK | R20: =IF(B20="","",IF(AND(M20="Approved",N20<>"",O20<>"",Q20="OK"),"Ready","Not yet")) -> Not yet
A21: D20 | B21: dysphagia | C21: medium | D21: dys | phag | ia | E21: prefix | root | suffix | F21: difficult, painful | eat, swallow | condition | G21: dys- | phag/o | -ia | H21: dys | phagia | I21: difficulty swallowing | J21: dis-FAY-jee-uh | L21: Claude (draft) | M21: Draft | Q21: =IF(B21="","",IF(SUBSTITUTE(SUBSTITUTE(D21," ",""),"|","")=B21,"OK","Split letters don't match")) -> OK | R21: =IF(B21="","",IF(AND(M21="Approved",N21<>"",O21<>"",Q21="OK"),"Ready","Not yet")) -> Not yet
A22: D21 | B22: polyuria | C22: medium | D22: poly | ur | ia | E22: prefix | root | suffix | F22: many, much | urine | condition | G22: poly- | ur/o | -ia | H22: poly | uria | I22: excessive urination | J22: pol-ee-YOOR-ee-uh | L22: Claude (draft) | M22: Draft | Q22: =IF(B22="","",IF(SUBSTITUTE(SUBSTITUTE(D22," ",""),"|","")=B22,"OK","Split letters don't match")) -> OK | R22: =IF(B22="","",IF(AND(M22="Approved",N22<>"",O22<>"",Q22="OK"),"Ready","Not yet")) -> Not yet
A23: D22 | B23: intravenous | C23: medium | D23: intra | ven | ous | E23: prefix | root | suffix | F23: within | vein | pertaining to | G23: intra- | ven/o | -ous | I23: pertaining to within a vein | J23: in-truh-VEE-nus | L23: Claude (draft) | M23: Draft | Q23: =IF(B23="","",IF(SUBSTITUTE(SUBSTITUTE(D23," ",""),"|","")=B23,"OK","Split letters don't match")) -> OK | R23: =IF(B23="","",IF(AND(M23="Approved",N23<>"",O23<>"",Q23="OK"),"Ready","Not yet")) -> Not yet
A24: D23 | B24: gastroenteritis | C24: hard | D24: gastr | o | enter | itis | E24: root | cv | root | suffix | F24: stomach | links the parts | intestines | inflammation | G24: gastr/o | o | enter/o | -itis | I24: inflammation of the stomach and intestines | J24: gas-troh-en-ter-EYE-tis | K24: The o stays between two roots, even though enter/o begins with a vowel. | L24: Claude (draft) | M24: Draft | Q24: =IF(B24="","",IF(SUBSTITUTE(SUBSTITUTE(D24," ",""),"|","")=B24,"OK","Split letters don't match")) -> OK | R24: =IF(B24="","",IF(AND(M24="Approved",N24<>"",O24<>"",Q24="OK"),"Ready","Not yet")) -> Not yet
A25: D24 | B25: electrocardiogram | C25: hard | D25: electr | o | cardi | o | gram | E25: root | cv | root | cv | suffix | F25: electricity | links the parts | heart | links the parts | record | G25: electr/o | o | cardi/o | o | -gram | I25: a record of the heart's electrical activity | J25: ee-lek-troh-KAR-dee-oh-gram | L25: Claude (draft) | M25: Draft | Q25: =IF(B25="","",IF(SUBSTITUTE(SUBSTITUTE(D25," ",""),"|","")=B25,"OK","Split letters don't match")) -> OK | R25: =IF(B25="","",IF(AND(M25="Approved",N25<>"",O25<>"",Q25="OK"),"Ready","Not yet")) -> Not yet
A26: D25 | B26: osteoarthritis | C26: hard | D26: oste | o | arthr | itis | E26: root | cv | root | suffix | F26: bone | links the parts | joint | inflammation | G26: oste/o | o | arthr/o | -itis | I26: inflammation of bone and joint; degenerative joint disease | J26: os-tee-oh-ar-THRY-tis | L26: Claude (draft) | M26: Draft | Q26: =IF(B26="","",IF(SUBSTITUTE(SUBSTITUTE(D26," ",""),"|","")=B26,"OK","Split letters don't match")) -> OK | R26: =IF(B26="","",IF(AND(M26="Approved",N26<>"",O26<>"",Q26="OK"),"Ready","Not yet")) -> Not yet
A27: D26 | B27: cholecystectomy | C27: hard | D27: chol | e | cyst | ectomy | E27: root | cv | root | suffix | F27: bile, gall | links the parts | bladder, sac | surgical removal | G27: chol/e | e | cyst/o | -ectomy | I27: surgical removal of the gallbladder | J27: koh-lee-sis-TEK-tuh-mee | K27: chol/e uses e as its combining vowel, not o. | L27: Claude (draft) | M27: Draft | Q27: =IF(B27="","",IF(SUBSTITUTE(SUBSTITUTE(D27," ",""),"|","")=B27,"OK","Split letters don't match")) -> OK | R27: =IF(B27="","",IF(AND(M27="Approved",N27<>"",O27<>"",Q27="OK"),"Ready","Not yet")) -> Not yet
A28: D27 | B28: hepatosplenomegaly | C28: hard | D28: hepat | o | splen | o | megaly | E28: root | cv | root | cv | suffix | F28: liver | links the parts | spleen | links the parts | enlargement | G28: hepat/o | o | splen/o | o | -megaly | I28: enlargement of the liver and spleen | J28: hep-uh-toh-splee-noh-MEG-uh-lee | L28: Claude (draft) | M28: Draft | Q28: =IF(B28="","",IF(SUBSTITUTE(SUBSTITUTE(D28," ",""),"|","")=B28,"OK","Split letters don't match")) -> OK | R28: =IF(B28="","",IF(AND(M28="Approved",N28<>"",O28<>"",Q28="OK"),"Ready","Not yet")) -> Not yet
A29: D28 | B29: myocardial | C29: hard | D29: my | o | cardi | al | E29: root | cv | root | suffix | F29: muscle | links the parts | heart | pertaining to | G29: my/o | o | cardi/o | -al | I29: pertaining to the heart muscle | J29: my-oh-KAR-dee-ul | L29: Claude (draft) | M29: Draft | Q29: =IF(B29="","",IF(SUBSTITUTE(SUBSTITUTE(D29," ",""),"|","")=B29,"OK","Split letters don't match")) -> OK | R29: =IF(B29="","",IF(AND(M29="Approved",N29<>"",O29<>"",Q29="OK"),"Ready","Not yet")) -> Not yet
A30: D29 | B30: pericardiocentesis | C30: hard | D30: peri | cardi | o | centesis | E30: prefix | root | cv | suffix | F30: around | heart | links the parts | surgical puncture to remove fluid | G30: peri- | cardi/o | o | -centesis | I30: surgical puncture to remove fluid from the sac around the heart | J30: pair-ih-kar-dee-oh-sen-TEE-sis | L30: Claude (draft) | M30: Draft | Q30: =IF(B30="","",IF(SUBSTITUTE(SUBSTITUTE(D30," ",""),"|","")=B30,"OK","Split letters don't match")) -> OK | R30: =IF(B30="","",IF(AND(M30="Approved",N30<>"",O30<>"",Q30="OK"),"Ready","Not yet")) -> Not yet
A31: D30 | B31: otorhinolaryngology | C31: hard | D31: ot | o | rhin | o | laryng | o | logy | E31: root | cv | root | cv | root | cv | suffix | F31: ear | links the parts | nose | links the parts | larynx, voice box | links the parts | study of | G31: ot/o | o | rhin/o | o | laryng/o | o | -logy | I31: the study of the ear, nose and throat (ENT) | J31: oh-toh-ry-noh-lair-in-GOL-uh-jee | L31: Claude (draft) | M31: Draft | Q31: =IF(B31="","",IF(SUBSTITUTE(SUBSTITUTE(D31," ",""),"|","")=B31,"OK","Split letters don't match")) -> OK | R31: =IF(B31="","",IF(AND(M31="Approved",N31<>"",O31<>"",Q31="OK"),"Ready","Not yet")) -> Not yet
Q32: =IF(B32="","",IF(SUBSTITUTE(SUBSTITUTE(D32," ",""),"|","")=B32,"OK","Split letters don't match")) | R32: =IF(B32="","",IF(AND(M32="Approved",N32<>"",O32<>"",Q32="OK"),"Ready","Not yet"))
Q33: =IF(B33="","",IF(SUBSTITUTE(SUBSTITUTE(D33," ",""),"|","")=B33,"OK","Split letters don't match")) | R33: =IF(B33="","",IF(AND(M33="Approved",N33<>"",O33<>"",Q33="OK"),"Ready","Not yet"))
Q34: =IF(B34="","",IF(SUBSTITUTE(SUBSTITUTE(D34," ",""),"|","")=B34,"OK","Split letters don't match")) | R34: =IF(B34="","",IF(AND(M34="Approved",N34<>"",O34<>"",Q34="OK"),"Ready","Not yet"))
Q35: =IF(B35="","",IF(SUBSTITUTE(SUBSTITUTE(D35," ",""),"|","")=B35,"OK","Split letters don't match")) | R35: =IF(B35="","",IF(AND(M35="Approved",N35<>"",O35<>"",Q35="OK"),"Ready","Not yet"))
Q36: =IF(B36="","",IF(SUBSTITUTE(SUBSTITUTE(D36," ",""),"|","")=B36,"OK","Split letters don't match")) | R36: =IF(B36="","",IF(AND(M36="Approved",N36<>"",O36<>"",Q36="OK"),"Ready","Not yet"))
Q37: =IF(B37="","",IF(SUBSTITUTE(SUBSTITUTE(D37," ",""),"|","")=B37,"OK","Split letters don't match")) | R37: =IF(B37="","",IF(AND(M37="Approved",N37<>"",O37<>"",Q37="OK"),"Ready","Not yet"))
Q38: =IF(B38="","",IF(SUBSTITUTE(SUBSTITUTE(D38," ",""),"|","")=B38,"OK","Split letters don't match")) | R38: =IF(B38="","",IF(AND(M38="Approved",N38<>"",O38<>"",Q38="OK"),"Ready","Not yet"))
Q39: =IF(B39="","",IF(SUBSTITUTE(SUBSTITUTE(D39," ",""),"|","")=B39,"OK","Split letters don't match")) | R39: =IF(B39="","",IF(AND(M39="Approved",N39<>"",O39<>"",Q39="OK"),"Ready","Not yet"))
Q40: =IF(B40="","",IF(SUBSTITUTE(SUBSTITUTE(D40," ",""),"|","")=B40,"OK","Split letters don't match")) | R40: =IF(B40="","",IF(AND(M40="Approved",N40<>"",O40<>"",Q40="OK"),"Ready","Not yet"))
...

Sheet Build Cases
A1: Case ID | B1: Level | C1: Program | D1: Case text | E1: Question | F1: Answer parts (in order) | G1: Tray tiles (12: answer + distractors) | H1: Pronunciation | I1: Body part affected | J1: What it names | K1: Good to know | L1: Written by | M1: Status | N1: Approved by | O1: Approval date | P1: Reviewer notes | Q1: Game-ready?
A2: B01 | B2: easy | C2: All programs | D2: A patient reports burning pain in the upper abdomen after meals. An endoscopy shows that the lining of the stomach is red and inflamed. | E2: What is the diagnosis? | F2: gastr/o + -itis | G2: peri- + epi- + gastr/o + enter/o + hepat/o + esophag/o + -itis + -algia + -ectomy + -ic + -um + -a | H2: gas-TRY-tis | I2: Stomach · digestive system | J2: Condition (diagnosis) | K2: Common causes include H. pylori infection, NSAID pain relievers and alcohol. Compare gastralgia, which names only the pain. | L2: Claude (draft) | M2: Draft | Q2: =IF(D2="","",IF(AND(M2="Approved",N2<>"",O2<>""),"Ready","Not yet")) -> Not yet
A3: B02 | B3: easy | C3: All programs | D3: A 16-year-old has fever and pain in the lower right abdomen. The surgeon decides the appendix must come out. | E3: What is this surgery called? | F3: append/o + -ectomy | G3: peri- + sub- + append/o + col/o + gastr/o + enter/o + -ectomy + -otomy + -ostomy + -itis + -ix + -ices | H3: ap-en-DEK-tuh-mee | I3: Appendix · digestive system | J3: Procedure (surgery) | K3: -ectomy removes a part; -otomy only cuts into it. The condition that leads to this surgery is appendicitis, which uses a different form of the root: appendic/o. | L3: Claude (draft) | M3: Draft | Q3: =IF(D3="","",IF(AND(M3="Approved",N3<>"",O3<>""),"Ready","Not yet")) -> Not yet
A4: B03 | B4: easy | C4: All programs | D4: While examining the abdomen, the provider feels the edge of the liver well below the right rib margin. It is larger than normal. | E4: What is this exam finding called? | F4: hepat/o + -megaly | G4: peri- + hyper- + hepat/o + splen/o + cardi/o + nephr/o + -megaly + -itis + -logy + -ic + -a + -um | H4: hep-uh-toh-MEG-uh-lee | I4: Liver · digestive system | J4: Sign (exam finding) | K4: An enlarged liver is a sign, not a diagnosis. It can come from hepatitis, heart failure, fatty liver disease and other causes. | L4: Claude (draft) | M4: Draft | Q4: =IF(D4="","",IF(AND(M4="Approved",N4<>"",O4<>""),"Ready","Not yet")) -> Not yet
A5: B04 | B5: easy | C5: All programs | D5: An older adult says her knees and fingers ache, especially in the morning. On exam there is no redness or swelling. | E5: What term names what she is describing? | F5: arthr/o + -algia | G5: peri- + sub- + arthr/o + oste/o + my/o + chondr/o + -algia + -itis + -plasty + -scopy + -um + -a | H5: ar-THRAL-jee-uh | I5: Joints · musculoskeletal system | J5: Symptom | K5: Arthralgia is joint pain the patient reports. Arthritis means the joint is inflamed, which usually brings swelling, warmth or redness. | L5: Claude (draft) | M5: Draft | Q5: =IF(D5="","",IF(AND(M5="Approved",N5<>"",O5<>""),"Ready","Not yet")) -> Not yet
A6: B05 | B6: easy | C6: EMT | D6: An EMT arrives to find a patient struggling to breathe. The patient's lips and fingertips have turned a bluish color. | E6: What is this sign called? | F6: cyan/o + -osis | G6: an- + poly- + cyan/o + erythr/o + leuk/o + hemat/o + -osis + -cyte + -emia + -oma + -a + -ae | H6: sy-uh-NOH-sis | I6: Skin and mucous membranes; reflects blood oxygen | J6: Sign | K6: Cyanosis signals low oxygen in the blood. Central cyanosis (lips, tongue) is more concerning than bluish hands or feet alone. | L6: Claude (draft) | M6: Draft | Q6: =IF(D6="","",IF(AND(M6="Approved",N6<>"",O6<>""),"Ready","Not yet")) -> Not yet
A7: B06 | B7: easy | C7: Dental | D7: During a cleaning, the hygienist notes red, puffy gums that bleed easily when probed. The teeth and bone are healthy. | E7: What condition does the patient have? | F7: gingiv/o + -itis | G7: peri- + sub- + gingiv/o + odont/o + gloss/o + stomat/o + -itis + -ectomy + -algia + -al + -a + -um | H7: jin-jih-VY-tis | I7: Gums · oral cavity | J7: Condition (diagnosis) | K7: Gingivitis is the early, reversible stage of gum disease. Without treatment it can progress to periodontitis, which damages bone. | L7: Claude (draft) | M7: Draft | Q7: =IF(D7="","",IF(AND(M7="Approved",N7<>"",O7<>""),"Ready","Not yet")) -> Not yet
A8: B07 | B8: easy | C8: Dental | D8: A patient calls the dental office with a throbbing pain in a lower back tooth that gets worse with cold drinks. | E8: What is the medical term for this complaint? | F8: odont/o + -algia | G8: peri- + endo- + odont/o + gingiv/o + gloss/o + cheil/o + -algia + -itis + -logy + -ectomy + -a + -um | H8: oh-don-TAL-jee-uh | I8: Tooth · oral cavity | J8: Symptom | K8: Odontalgia is the formal term for a toothache. odont/o and dent/o both mean tooth. | L8: Claude (draft) | M8: Draft | Q8: =IF(D8="","",IF(AND(M8="Approved",N8<>"",O8<>""),"Ready","Not yet")) -> Not yet
A9: B08 | B9: easy | C9: All programs | D9: An X-ray shows compression fractures in three of the bones that make up the spinal column. | E9: Using the plural form, what are these bones called? | F9: vertebr/o + -ae | G9: inter- + sub- + vertebr/o + cost/o + crani/o + bronch/o + -al + -ectomy + -a + -ae + -us + -i | H9: VER-tuh-bray | I9: Spinal column · skeletal system | J9: Body part (plural) | K9: Words ending in -a form the plural with -ae: one vertebra, two vertebrae. | L9: Claude (draft) | M9: Draft | Q9: =IF(D9="","",IF(AND(M9="Approved",N9<>"",O9<>""),"Ready","Not yet")) -> Not yet
A10: B09 | B10: easy | C10: All programs | D10: A chest X-ray shows mucus blocking both of the main airways that branch off the trachea into the lungs. | E10: Using the plural form, what are these two airways called? | F10: bronch/o + -i | G10: endo- + peri- + bronch/o + trache/o + laryng/o + pneumon/o + -itis + -scopy + -us + -i + -a + -ae | H10: BRONG-ky | I10: Lower airway · respiratory system | J10: Body part (plural) | K10: Words ending in -us form the plural with -i: one bronchus, two bronchi. | L10: Claude (draft) | M10: Draft | Q10: =IF(D10="","",IF(AND(M10="Approved",N10<>"",O10<>""),"Ready","Not yet")) -> Not yet
